Workbook

Sheet Главная
E2: Время работы: Пн-Пт 10:00 - 18:00 | H2: Сб-Вс Выходной
E4: 8 495 744 35 42 | G4: info@interactive-project.ru
E6: 8 495 744 35 72
B8: Компания-производитель интерактивного оборудования и программного обеспечения для образовательных учреждений с 2007 года
D10: Каталог товаров

Sheet Прайс лист
C3: Наименование | D3: Розничная цена (включая НДС 7%)
C4: Интерактивные столы
C5: Интерактивный стол Project touch 27 дюймов тип М | D5: 175000
C6: Интерактивный стол Project touch 32 дюймов тип М | D6: 180000
C7: Интерактивный стол Project touch 32 дюйма | D7: 205000
C8: Интерактивный стол Project touch 43 дюйма | D8: 215000
C9: Интерактивный стол Project touch 50 дюймов | D9: 280000
C10: Интерактивный стол Project touch 55 дюймов | D10: 310000
C11: Интерактивная панель
C12: Интерактивная панель Project touch 65 дюймов - тонкий корпус | D12: 300000
C13: Интерактивная панель Project touch 75 дюймов - тонкий корпус | D13: 400000
C14: Стойка перекатная для панели | D14: 45000
C15: Интерактивный пол
C16: Интерактивный пол в корпусе кинект | D16: 475000
C17: Интерактивный пол в корпусе | D17: 465000
C18: Интерактивный пол без корпуса | D18: 400000
C19: Интерактивный пол без проектора | D19: 295000
C20: Интерактивный пол мобильный
C21: Мобильный интерактивный пол Светлячок Оптима Декор | D21: 575000
C22: Мобильный интерактивный пол Светлячок Оптима | D22: 550000
C23: Мобильный интерактивный пол Светлячок Бюджет | D23: 395000
C24: Интерактивная песочница
C25: Интерактивная песочница Океан | D25: 325000
C26: Интерактивная песочница Мираж | D26: 395000
C27: Интерактивная песочница Жемчужина | D27: 435000
C28: Интерактивная песочница Жемчужина с сенсорным экраном | D28: 475000
C29: Интерктивная песочница ОВЗ | D29: 475000
C30: Интерактивная песочница с дизайнерским оформлением Жираф | D30: 500000
C31: Интерактивная стена "Кидалки"
C32: Интерактивная стена "Кидалки" в корпусе (кинект) | D32: 490000
C33: Интерактивная стена "Кидалки" без корпуса | D33: 415000
C34: Интерактивная стена "Кидалки" без проектора | D34: 310000
C35: Интерактивная стена "Ожившие рисунки"
C36: Интерактивная стена "Ожившие рисунки" в корпусе (кинект) | D36: 520000
C37: Интерактивная стена "Ожившие рисунки" без корпуса | D37: 445000
C38: Интерактивная стена "Ожившие рисунки" без проектора | D38: 340000
C39: Интерактивная стена "Ожившие рисунки" мобильный комплект | D39: 520000
C40: Интерактивная стена "Спортбол"
C41: Интерактивная стена "Спортбол" в корпусе (кинект) | D41: 475000
C42: Интерактивная стена "Спортбол" без корпуса | D42: 400000
...

Sheet Стол
B2: В Главное меню | C2: Переход на Прайс-лист | E2: Интерактивные столы
B4: Интерактивный стол — это оборудование со встроенным компьютером на базе ОС Windows, за счет большого сенсорного экрана позволяющий с комфортом работать нескольким пользователям. Размещение интерактивного стола на полу, без фиксации к полу. Интерактивный стол, как и компьютер, может выполнять множество функций, но чаще всего его используют для обучения специальным программным обеспечением. На свои столы мы устанавливаем программное обеспечение для дошкольников состоящее из 313 игр. Также возможно установить любое программное обеспечение, работающее под ОС Windows и поддерживающее функцию работы с сенсорным экраном, в том числе редактор интерактивных заданий «Методист». Модели интерактивных столов отличаются размером экрана и типом корпуса. Все столы имеют прочный металлический корпус, устойчивый и антивандальный. Варианты исполнения интерактивных столов: тип корпуса М - данный стол предназначен для самых маленьких деток, его высота всего 45 см, размер диагонали 27 и 32 дюйма, базовый встроенный компьютер на базе процессора AMD. Стол имеет сенсор распознавания касаний и встроенный звук. тип корпуса Стандарт - данный стол предназначен для детей и взрослых, стол имеет наклонную столешницу от 0 до 90 градусов, возможна высота двух типов детская 66 см и 89 см стандартная. Размер диагонали от 32 до 55 дюймов. Базовый встроенный компьютер на базе процессора AMD. Стол имеет сенсор распознавания касаний и встроенный звук. Все конфигурации встроенного компьютера можно улучшать под требования заказчика. Также на выбор есть различные варианты цвета столов. Монтаж интерактивного стола не требуется. Все, что необходимо, это распаковать оборудование, поставить в удобное для работы место и подключить к электрической сети. Оборудование полностью готово к работе.
B6: Модель | C6: ='Прайс лист'!C7 -> Интерактивный стол Project touch 32 дюйма | D6: ='Прайс лист'!C8 -> Интерактивный стол Project touch 43 дюйма | E6: ='Прайс лист'!C9 -> Интерактивный стол Project touch 50 дюймов | F6: ='Прайс лист'!C10 -> Интерактивный стол Project touch 55 дюймов | G6: ='Прайс лист'!C5 -> Интерактивный стол Project touch 27 дюймов тип М | H6: ='Прайс лист'!C6 -> Интерактивный стол Project touch 32 дюймов тип М
B8: Базовая цена (включая НДС 7%) | C8: ='Прайс лист'!D7 -> 205000 | D8: ='Прайс лист'!D8 -> 215000 | E8: ='Прайс лист'!D9 -> 280000 | F8: ='Прайс лист'!D10 -> 310000 | G8: ='Прайс лист'!D5 -> 175000 | H8: ='Прайс лист'!D6 -> 180000
B9: Габариты (ДхШхВ) (мм) | C9: 825х520х660 или 890 | D9: 1170х730х660 или 890 | E9: 1230х760х660 или 890 | F9: 1360х830х660 или 890 | G9: 990х600х450 | H9: 990х600х450
B10: Характеристики экрана, сенсора, звук | C10: экран 32", разрешение HD 1280x720, угол обзора 178°, 20 касаний, звук 10 Вт | D10: экран 43", разрешение Full HD 1920x1080, угол обзора 178°, 20 касаний, звук 10 Вт | E10: экран 50", разрешение Full HD 1920x1080, угол обзора 178°, 20 касаний, звук 10 Вт | F10: экран 55", разрешение Full HD 1920x1080, угол обзора 178°, 20 касаний, звук 10 Вт | G10: экран 27", разрешение Full HD 1920x1080, угол обзора 178°, 20 касаний, звук 6 Вт | H10: экран 32", разрешение HD 1280x720, угол обзора 178°, 20 касаний, звук 10 Вт
B11: Характеристики компьютера. Улучшение характеристик - по Запросу | C11: 2-х ядерный 3.2 Ггц / 120 SSD / 4Gb / Wi-fi/ Windows 10 Базовая комплектация* Улучшение характеристик по запросу | D11: 2-х ядерный 3.2 Ггц / 120 SSD / 4Gb / Wi-fi/ Windows 10 Базовая комплектация* Улучшение характеристик по запросу | E11: 2-х ядерный 3.2 Ггц / 120 SSD / 4Gb / Wi-fi/ Windows 10 Базовая комплектация* Улучшение характеристик по запросу | F11: 2-х ядерный 3.2 Ггц / 120 SSD / 4Gb / Wi-fi/ Windows 10 Базовая комплектация* Улучшение характеристик по запросу | G11: 2-х ядерный 3.2 Ггц / 120 SSD / 4Gb / Wi-fi/ Windows 10 Базовая комплектация* Улучшение характеристик по запросу | H11: 2-х ядерный 3.2 Ггц / 120 SSD / 4Gb / Wi-fi/ Windows 10 Базовая комплектация* Улучшение характеристик по запросу
B12: Базовое ПО | C12: Комплект обучающих игр 313 шт. | D12: Комплект обучающих игр 313 шт. | E12: Комплект обучающих игр 313 шт. | F12: Комплект обучающих игр 313 шт. | G12: Комплект обучающих игр 313 шт. | H12: Комплект обучающих игр 313 шт.
B13: Дополнительное ПО:
B14: "Методист" эл. дистрибутив | C14: РРЦ + 15000 ₽ | D14: РРЦ + 15000 ₽ | E14: РРЦ + 15000 ₽ | F14: РРЦ + 15000 ₽ | G14: РРЦ + 15000 ₽ | H14: РРЦ + 15000 ₽
B15: Логомер-3 | C15: РРЦ + 31 000 ₽ | D15: РРЦ + 31 000 ₽ | E15: РРЦ + 31 000 ₽ | F15: РРЦ + 31 000 ₽ | G15: РРЦ + 31 000 ₽ | H15: РРЦ + 31 000 ₽
B16: Мерсибо плюс 3 | C16: РРЦ + 25 500 ₽ | D16: РРЦ + 25 500 ₽ | E16: РРЦ + 25 500 ₽ | F16: РРЦ + 25 500 ₽ | G16: РРЦ + 25 500 ₽ | H16: РРЦ + 25 500 ₽
B17: Мерсибо интерактив | C17: РРЦ + 14 000 ₽ | D17: РРЦ + 14 000 ₽ | E17: РРЦ + 14 000 ₽ | F17: РРЦ + 14 000 ₽ | G17: РРЦ + 14 000 ₽ | H17: РРЦ + 14 000 ₽
B18: Цвет | C18: 22 цвета на выбор | D18: 22 цвета на выбор | E18: 22 цвета на выбор | F18: 22 цвета на выбор | G18: 22 цвета на выбор | H18: 22 цвета на выбор
B19: Вес | C19: Высота 660мм - 63 кг Высота 890мм - 67 кг | D19: Высота 660мм - 93 кг Высота 890мм - 97 кг | E19: Высота 660мм - 75 кг Высота 890мм - 82 кг | F19: Высота 660мм - 113 кг Высота 890мм - 117 кг | G19: 45 кг | H19: 45 кг
B20: Комплект поставки | C20: 1. Интеративный Стол 2. Пульт 3. Технический паспорт 4. Комплект из 313 обучающих игр 5. Сертификат 6. Гарантийный талон на 1 год | D20: 1. Интеративный Стол 2. Пульт 3. Технический паспорт 4. Комплект из 313 обучающих игр 5. Сертификат 6. Гарантийный талон на 1 год | E20: 1. Интеративный Стол 2. Пульт 3. Технический паспорт 4. Комплект из 313 обучающих игр 5. Сертификат 6. Гарантийный талон на 1 год | F20: 1. Интеративный Стол 2. Пульт 3. Технический паспорт 4. Комплект из 313 обучающих игр 5. Сертификат 6. Гарантийный талон на 1 год | G20: 1. Интеративный Стол 2. Технический паспорт 3. Комплект из 313 обучающих игр 4. Сертификат 5. Гарантийный талон на 1 год | H20: 1. Интеративный Стол 2. Пульт 3. Технический паспорт 4. Комплект из 313 обучающих игр 5. Сертификат 6. Гарантийный талон на 1 год
B22: Количество мест: | C22: 1 | D22: 1 | E22: 1 | F22: 1 | G22: 1 | H22: 1
B23: Габариты (м.) | C23: 875 х 570 х 700 или 930 | D23: 1220х780х700 или 930 | E23: 1280х810х700 или 930 | F23: 1410х880х700 или 930 | G23: 1040х650х500 | H23: 1040х650х500
B24: Вес (кг.) | C24: 72 | D24: 77 | E24: 82 | F24: 87 | G24: 45 | H24: 45
B25: Объём
B27: В Главное меню | C27: Переход на Прайс-лист | E27: Интерактивные столы

Sheet Панель
B2: В Главное меню | C2: Переход на Прайс-лист | D2: Интерактивные панели
B4: Интерактивная панель - это интерактивный экран со встроенным компьютером на базе ОС Windows, позволяющий с комфортом работать нескольким пользователям. Интерактивная панель, как и компьютер, может выполнять множество функций, но чаще всего его используют для обучения специальным развивающим ПО. На свои интерактивные панели мы устанавливаем программное обеспечения для дошкольников состоящее из 313 мини-игр. Также возможно установить любое программное обеспечение, работающее под ОС Windows и поддерживающее функцию работы с сенсорным экраном, в том числе Редактор интерактивных заданий «Методист». Тонкий тип корпуса имеет облегченный вес, металл толщиной 1,5 мм, окраска в типовой цвет. Размер диагонали 65 и 75 дюймов, компьютер на базе процессора Intel. Из преимуществ можно отметить облегченный вес, что позволяет с удобством размещать или перемещать оборудование. Все конфигурации встроенного компьютера можно улучшать под требования заказчика. Монтаж интерактивной панели происходит на стене при помощи специального крепления либо на перекатной стойке. Для монтажа на стену необходимо убедиться, что стена выдержит вес панели. Рекомендуется крепить панель на бетонной или кирпичной стене, не рекомендуется крепить панель на стену из гипсокартона. Для монтажа на перекатную стойку необходимо убедиться, что данная стойка рассчитана на вес интерактивной панели.
B6: Модель | C6: ='Прайс лист'!C12 -> Интерактивная панель Project touch 65 дюймов - тонкий корпус | E6: ='Прайс лист'!C13 -> Интерактивная панель Project touch 75 дюймов - тонкий корпус
B8: Базовая цена (включая НДС 7%) | C8: ='Прайс лист'!D12 -> 300000 | E8: ='Прайс лист'!D13 -> 400000
B9: Габаритные размеры (ДхШхГ) мм., Вес | C9: 1490х900х100 50 кг | E9: 1700х1040х110 60 кг
B10: Характеристики экрана, сенсора, звук | C10: экран 65", разрешение 4K 3840x2160, угол обзора 165/150°, 20 касаний, звук 10 Вт | E10: экран 75", разрешение 4K 3840x2160, угол обзора 165/150°, 20 касаний, звук 10 Вт
B11: Характеристики компьютера | C11: Intel i5 10-го поколения/ 240 SSD / 8Gb / Wi-fi/ Windows 10 Базовая комплектация* Улучшение характеристик по запросу | E11: Intel i5 10-го поколения/ 240 SSD / 8Gb / Wi-fi/ Windows 10 Базовая комплектация* Улучшение характеристик по запросу
B12: Разъемы для подключения устройств | C12: USB 3.0 - 3шт., USB 2.0 - 3шт., HDMI - 1шт., RJ45 - 1шт., WiFi, Audio in, Audio out | E12: USB 3.0 - 3шт., USB 2.0 - 3шт., HDMI - 1шт., RJ45 - 1шт., WiFi, Audio in, Audio out
B13: Базовое ПО | C13: Комплект обучающих игр 313 шт. | E13: Комплект обучающих игр 313 шт.
B14: Дополнительное ПО:
B15: "Методист" эл. дистрибутив | C15: РРЦ + 15000 ₽ | E15: РРЦ + 15000 ₽
B16: Логомер-3 | C16: РРЦ + 31 000 ₽ | E16: РРЦ + 31 000 ₽
B17: Мерсибо плюс 3 | C17: РРЦ + 25 500 ₽ | E17: РРЦ + 25 500 ₽
B18: Мерсибо интерактив | C18: РРЦ + 14 000 ₽ | E18: РРЦ + 14 000 ₽
B19: Перекатная стойка | C19: + 45000 ₽ | E19: + 45000 ₽
B20: В комплект входят: | C20: 1. Панель 2. Стилус 3. Настенное крепление или стойка 4. Пульт 5. Сертификат 6. Гарантийный талон на 1 год | E20: 1. Панель 2. Стилус 3. Настенное крепление или стойка 4. Пульт 5. Сертификат 6. Гарантийный талон на 1 год
B22: Количество мест: | C22: 1 | E22: 1
B23: Габариты (м.) | C23: 1,75*1,1*0,3 | E23: 1,9*1,2*0,3
B24: Вес (кг.) | C24: 60 | E24: 70
B25: Объём | C25: 0.6 | E25: 0.7
B27: В Главное меню | C27: Переход на Прайс-лист | D27: Интерактивные панели

Sheet Пол
B2: В Главное меню | C2: Переход на Прайс-лист
B4: Интерактивный комплект оборудования с проекцией на пол и обратной связью на действия детей на этой проекции. Продукт востребован в дошкольных образовательных учреждениях, развивающих центрах, а также в игровых комнатах и парках. Различается по типу использования программного обеспечения и вариантами размещения и исполнения. Программное обеспечение делится на различные игровые блоки: Развивающий блок, развлекательный блок, Оздоровительная физкультура, а также есть возможность установки редактора интерактивных заданий «Методист». Оборудование интерактивного пола состоит из основных компонентов: Проектор, датчик, компьютер и программного обеспечения. Есть несколько вариантов комплектации, которые отличаются наличием защитного корпуса и характеристиками проектора, также характеристиками датчика детекции. Монтаж системы на потолок. Основание потолка (желательно бетон) должно выдержать вес оборудования около 25 килограмм. Не допускается монтаж оборудования на подвесной потолок без закладных под оборудование. Максимальный размер проекции зависит от высоты размещения, чем выше закреплен комплект, тем больше проекция, но есть ограничения по максимальной высоте размещения.
B6: Модель | C6: ='Прайс лист'!C16 -> Интерактивный пол в корпусе кинект | D6: ='Прайс лист'!C17 -> Интерактивный пол в корпусе | E6: ='Прайс лист'!C18 -> Интерактивный пол без корпуса | F6: ='Прайс лист'!C19 -> Интерактивный пол без проектора
B8: Базовая цена (включая НДС 7%) | C8: ='Прайс лист'!D16 -> 475000 | D8: ='Прайс лист'!D17 -> 465000 | E8: ='Прайс лист'!D18 -> 400000 | F8: ='Прайс лист'!D19 -> 295000
B9: Характеристики проектора | C9: Яркость 3500 Лм Разрешение 1280*800 звук 10 Вт | D9: Яркость 3500 Лм Разрешение 1280*800 звук 10 Вт | E9: Яркость 4500 Лм Разрешение 1280*800 звук 10 Вт | F9: Рекомендуемые характеристики Яркость 3800 Лм Разрешение 1280*800 звук 10 Вт
B10: Характеристики компьютера | C10: 3.0 Ghz /4Gb/SSD240 Windows 10 | D10: 3.0 Ghz /4Gb/SSD240 Windows 10 | E10: 3.0 Ghz /4Gb/SSD240 Windows 10 | F10: 3.0 Ghz /4Gb/SSD240 Windows 10
B11: Датчик детекции | C11: Кинект | D11: Камера ИК | E11: Камера ИК | F11: Камера ИК
B12: Основное программное обеспечение и блок игр на выбор | C12: 1) Программа распознавания касаний. 2) Блок игр на выбор: Развивающий, развлекательный или оздоровительная физкультура, более 40 игр. | D12: 1) Программа распознавания касаний. 2) Блок игр на выбор: Развивающий, развлекательный или оздоровительная физкультура, более 40 игр. | E12: 1) Программа распознавания касаний. 2) Блок игр на выбор: Развивающий, развлекательный или оздоровительная физкультура, более 40 игр. | F12: 1) Программа распознавания касаний. 2) Блок игр на выбор: Развивающий, развлекательный или оздоровительная физкультура, более 40 игр.
B13: Дополнительный блок игр | C13: Развлекательный + 30 000 ₽ Развивающий + 30 000 ₽ Оздоровительная физкультура +30 000 ₽ "Методист" эл. дистрибутив" +15000₽ | D13: Развлекательный + 30 000 ₽ Развивающий + 30 000 ₽ "Методист" эл. дистрибутив" +15000₽ | E13: Развлекательный + 30 000 ₽ Развивающий + 30 000 ₽ "Методист" эл. дистрибутив +15000₽ | F13: Развлекательный + 30 000 ₽ Развивающий + 30 000 ₽ "Методист" эл. дистрибутив +15000₽
B14: Размер корпуса (ДхШхВ) (мм) | C14: 450 х 420 х 340 | D14: 450 х 420 х 340 | E14: 445 х 365 х 110 | F14: 445 х 365 х 110
B15: Вес в сборе | C15: 25 кг | D15: 25 кг | E15: 15 кг | F15: 5 кг
B16: В комплект входят: | C16: 1. Корпус (с компьютером, проектором, камерой Kinect) 2. Крепление 3. Беспроводные клавиатура и мышь 4. Пульт 5. Составное белое покрытие 6. Методическое пособие 7. Технический паспорт 8. Программное обеспечение Интерактив. Блок интерактивных игр - более 40 шт. 9. Сертификат 10. Гарантийный талон 1 год | D16: 1. Корпус (с компьютером, проектором, камерой) 2. Крепление 3. Беспроводные клавиатура и мышь 4. Пульт 5. Составное белое покрытие 6. Методическое пособие 7. Технический паспорт 8. Программное обеспечение Интерактив. Блок интерактивных игр - более 40 шт. 9. Сертификат 10. Гарантийный талон 1 год | E16: 1. Компьютер + крепление 2. Проектор + крепление 3. Камера 4. Беспроводные клавиатура и мышь 5. Составное белое покрытие 6. Технический паспорт 7. Программное обеспечение Интерактив. Блок интерактивных игр - более 40 шт. 8. Сертификат 9. Гарантийный талон 1 год | F16: 1. Компьютер + крепление 2. Камера 3. Беспроводные клавиатура и мышь 4. Составное белое покрытие 5. Технический паспорт 6. Программное обеспечение Интерактив. Блок интерактивных игр - более 40 шт. 7. Сертификат 8. Гарантийный талон 1 год
B18: Количество мест | C18: 1 | D18: 1 | E18: 1 | F18: 1
B19: Упакованные комплекты
B20: Габариты (м.) | C20: 0,5*0,5*0,4 | D20: 0,5*0,5*0,4 | E20: 0,4*0,5*0,35 | F20: 0.4*0.4*0.2
B21: Вес (кг.) | C21: 30 | D21: 30 | E21: 20 | F21: 2
B22: Объём | C22: 0.05 | D22: 0.1 | E22: 0.07 | F22: 0.032
B24: В Главное меню | C24: Переход на Прайс-лист

Sheet Моб.пол
B2: В Главное меню | C2: Переход на Прайс-лист | D2: ='Прайс лист'!C20 -> Интерактивный пол мобильный
B4: Интерактивный мобильный комплект оборудования с проекцией на пол и обратной связью на действия детей на этой проекции. Данный продукт востребован в дошкольных образовательных учреждениях и развивающих центрах благодаря своей мобильности. Не требует монтажа и настройки. Различается по типу использования программного обеспечения и вариантами размещения и исполнения. Программное обеспечение делится на различные игровые блоки: Развивающий блок, развлекательный блок, оздоровительная физкультура, а также есть возможность установки редактора интерактивных заданий «Методист». Отличие в комплектах обородувания состоит в том, что в модели "Оптима" используется лазерный проектор с большой засветкой проекции и длительным ресурсом лампы, а модели "Бюджет" значительно меньше проекция и используется ламповый проектор. Во всех моделях мобильного интерактивного пола есть сенсорный экран для удобства выбора игр, а само оборудование уже идет полностью настроенное и готовое к работе. | F4: Интерактивный комплекс 2 в 1 стена и пол — универсальное оборудование для детских садов, школ, детских развивающих и развлекательных центров. Проекция может быть направлена как на стену, так и на пол. При смене направления проекции не требуется настройка, достаточно просто установить комплект в нужное положение. К комплексу можно приобретать пакеты игр как интерактивного пола, так и стены. И, конечно, на оборудовании будет работать наш Редактор интерактивных заданий. Можно использовать игры в комплекте, создавать свои и проводить любые занятия на полу и стене. • Размер проекции на стене: 3,25 * 1,85 м.; • Размер проекции на полу: 3,13 * 1,73 м.; • Игровой пакет для пола, игровой пакет для стены; • Лазерный проектор с длительным ресурсом работы; • Не требует настройки.
B6: Модель | C6: ='Прайс лист'!C22 -> Мобильный интерактивный пол Светлячок Оптима | D6: ='Прайс лист'!C23 -> Мобильный интерактивный пол Светлячок Бюджет | E6: ='Прайс лист'!C21 -> Мобильный интерактивный пол Светлячок Оптима Декор | F6: ='Прайс лист'!C55 -> Интерактивный комплекс 2в1
B8: Базовая цена (включая НДС 7%) | C8: ='Прайс лист'!D22 -> 550000 | D8: ='Прайс лист'!D23 -> 395000 | E8: ='Прайс лист'!D21 -> 575000 | F8: ='Прайс лист'!D55 -> 625000
B9: Габариты (ДхШхВ) мм, вес. | C9: 870х470х470 40 кг | D9: 1210х550х460 45 кг | E9: 870х470х470 40 кг | F9: 140х440х730 40 кг
B10: Характеристики проектора | C10: Лазерный проектор Яркость 4000 Лм Разрешение 1920*1080 звук 10 Вт | D10: Ламповый проектор Яркость 3500 Лм Разрешение 1280*800 звук 10 Вт | E10: Лазерный проектор Яркость 4000 Лм Разрешение 1920*1080 звук 10 Вт | F10: Лазерный проектор яркость 4000 Лм Разрешение 1920*1080 звук 10 Вт
B11: Размер проекции | C11: 3,2 м х 1,8 м | D11: 2 м х 1,25 м | E11: 3,2 м х 1,8 м | F11: Размер проекции на полу: 3,13 м. * 1,73 м. Размер проекции на стене: 3,25 м. * 1,85 м.
B12: Характеристика компьютера | C12: 3.0 Ghz /4Gb/SSD240 Windows 10 | D12: 3.0 Ghz /4Gb/SSD240 Windows 10 | E12: 3.0 Ghz /4Gb/SSD240 Windows 10 | F12: 3.0 Ghz /4Gb/SSD240 Windows 10
B13: Датчик детекции | C13: Интерактивный датчик | D13: Интерактивный датчик | E13: Интерактивный датчик | F13: Интерактивный датчик
B14: Сенсорный экран для выбора игр | C14: 15 дюймов | D14: 15 дюймов | E14: 15 дюймов | F14: Не предусмотрено. Возможность управления играми с планшета *Опционально
B15: Основное программное обеспечение. Блок игр на выбор | C15: 1) Программа распознавания касаний. 2) Блок игр: Развивающий или Развлекательный или Оздоровительная физра 3) Игровой блок Сороконожка - 192 игры. | D15: 1) Программа распознавания касаний. 2) Блок игр: Развивающий или Развлекательный 3) Игровой блок Сороконожка - 192 игры. | E15: 1) Программа распознавания касаний. 2) Блок игр: Развивающий или Развлекательный или Оздоровительная физра 3) Игровой блок Сороконожка - 192 игры. | F15: 1) Программа распознавания касаний. 2) Блок игр для стены: "Кидалки-Обучалки" не менее 30 игр или на выбор любой подходящий игровой блок для стены 2) Блок игр для пола: "Развивающий" не менее 50 игр или на выбор любой игровой блок для пола
B16: Дополнительный блок игр | C16: Развлекательный + 30 000 ₽ Развивающий + 30 000 ₽ Оздоровительная физкультура +30 000 ₽ "Методист" эл. дистрибутив" +15000₽ | D16: Развлекательный + 30 000 ₽ Развивающий + 30 000 ₽ Оздоровительная физкультура +30 000 ₽ "Методист" эл. дистрибутив +15000₽ | E16: Развлекательный + 30 000 ₽ Развивающий + 30 000 ₽ Оздоровительная физкультура +30 000 ₽ "Методист" эл. дистрибутив +15000₽ | F16: Развлекательный для пола не менее 55 игр + 30 000 ₽ Развивающий для пола не менее 55 игр + 30 000 ₽ Оздоровительная физ-ра для пола не менее 40 игр+30 000 ₽ "Методист" эл. дистрибутив +15000₽ Раскраски не менее 10 игр+ 10 000 ₽ Спортбол не менее 20игр + 30 000 ₽ Ожившие рисунки не менее 13 эффектов со скан-модулем +75 000 ₽ Кидалки не менее 47 игр + 45 000 ₽
B17: Комплектация | C17: 1) Мобильный пол Светлячок Оптима 2) Клавиатура и мышь 3) Пульт для проектора 4) Защитный чехол 5) Технический паспорт 6) Гарантийный талон 7) Комплект мягкого напольного покрытия | D17: 1) Мобильный пол Светлячок бюджет 2) Клавиатура и мышь 3) Пульт для проектора 4) Защитный чехол 5) Технический паспорт 6) Гарантийный талон 7) Комплект мягкого напольного покрытия | E17: 1) Мобильный пол Светлячок Оптима Декор 2) Клавиатура и мышь 3) Пульт для проектора 4) Защитный чехол 5) Технический паспорт 6) Гарантийный талон 7) Комплект мягкого напольного покрытия | F17: 1. Единый металический корпус мобильного комплекса 2в1, 2. Подставка для напольной проекции, к которой крепится комплекс 3. Беспроводные клавиатура и мышь 4. Пульт для проектора 5. Блок игр для стены один или несколько в зависимости от комплектации 6. Блок игр для пола один или несколько в зависимости от комплектации 7. Технический паспорт 8. Сертификат 9. Гарантийный талон 10. Напольное покрытие * Опционально: Комлект мягких мячей-12шт
B19: Упакованные комплекты
B20: Габариты (м.) | C20: 0,6*0,8*0,9 | D20: 0,6*0,6*1,3 | E20: 0,6*0,8*0,9 | F20: 0,95*0,5*0,6
B21: Вес (кг.) | C21: 50 | D21: 50 | E21: 50 | F21: 45
B22: Объём | F22: *со скан модулем 1,05*,65*0,6 50 кг
B24: В Главное меню | C24: Переход на Прайс-лист

Sheet Песочница
B2: В Главное меню | C2: Переход на Прайс-лист | E2: ='Прайс лист'!C24 -> Интерактивная песочница
B4: Идеальное игровое пространство, чтобы создавать и исследовать собственные миры с горами, вулканами, морями, реками! Благодаря компьютерным технологиям на песке появляется дополненная реальность. Таким образом, песочница служит маленькой моделью окружающего мира. С интерактивной песочницей дети могут играть в песке круглый год. Естественные и привычные игры привлекают и завораживают. В большом помещении, со множеством аттракционов, дети обязательно подойдут к песочнице. В комплекте программного обеспечения также есть игры для поверхности, когда песок закрывается крышкой для песка и получается ровная поверхность. Что же касается самого песка, используемого в интерактивной песочнице, то в нашей песочнице можно использовать обычный речной песок, не обязательно кинетический. Благодаря яркому проектору картинку будет хорошо видно на любом песке. Мы производим песочницы двух типовых размеров мини и стандарт, песочница стандарт может комплектоваться сенсорным экраном для удобства выбора игр, а также на песочницу стандарт возможна установка ног высоко размера, для возможности пользования оборудования инвалидами колясочниками. К каждой модели интерактивной песочницы возможно установить программу для удаленного управления запуска игр. Песочница по умолчанию не комплектуется песком, при заказе оборудования песок заказывается отдельно. Сборка песочницы не сложная, после сборки и первичного запуска, может потребоваться повторная настройка оборудования.
B6: Модель | C6: ='Прайс лист'!C25 -> Интерактивная песочница Океан | D6: ='Прайс лист'!C26 -> Интерактивная песочница Мираж | E6: ='Прайс лист'!C27 -> Интерактивная песочница Жемчужина | F6: ='Прайс лист'!C28 -> Интерактивная песочница Жемчужина с сенсорным экраном | G6: ='Прайс лист'!C29 -> Интерктивная песочница ОВЗ | H6: ='Прайс лист'!C30 -> Интерактивная песочница с дизайнерским оформлением Жираф
B8: Преимущество модели | C8: Компактная и недорогая модель песочницы со оформлением наклейкой в стиле Океан. 26 игр для песка + 40 игр для крышки-стола резервуара. | D8: Средний корпус для песка, яркий и контрастный проектор, возможность индивидуальной окраски корпуса. Сенсорный экран для удобства выбора игр. 26 игр для песка + 40 игр для крышки-стола резервуара. | E8: Большой корпус для песка, яркий и контрастный проектор, возможность индивидуальной окраски корпуса. 26 игр для песка + 40 игр для крышки-стола резервуара. | F8: Большой корпус для песка, яркий и контрастный проектор, возможность индивидуальной окраски корпуса, сенсорный экран для удобства выбора игр. 26 игр для песка + 40 игр для крышки-стола резервуара. | G8: Большой корпус для песка, яркий и контрастный проектор, возможность ин, сенсорный экран для удобства выбора игр. Увеличенное пространство под корпусом песка для удобства использования инвалидами-колясочниками. 26 игр для песка + 40 игр для крышки-стола резервуара. | H8: Большой корпус для песка, яркий и контрастный проектор, дизайнерская оклейка корпуса в стиле Жираф, сенсорный экран для удобства выбора игр. 26 игр для песка + 40 игр для крышки-стола резервуара.
B9: Базовая цена (включая НДС 7%) | C9: ='Прайс лист'!D25 -> 325000 | D9: ='Прайс лист'!D26 -> 395000 | E9: ='Прайс лист'!D27 -> 435000 | F9: ='Прайс лист'!D28 -> 475000 | G9: ='Прайс лист'!D29 -> 475000 | H9: ='Прайс лист'!D30 -> 500000
B10: Размер (ВхШхГ) мм. | C10: 2000х980х660 | D10: 2150х1160х940 | E10: 2310х1610х1050 | F10: 2310х1610х1050 | G10: 2310х1610х1050 | H10: 2310х1610х1050
B11: Размер резервуара для песка, мм. | C11: 930х520х160 | D11: 1160х940х120 | E11: 1610х1050х180 | F11: 1610х1050х180 | G11: 1610х1050х180 | H11: 1610х1050х180
B12: Характеристики проектора | C12: Яркость 3400 Лм Разрешение 1280*800 звук 10 Вт | D12: Яркость 3500 Лм Разрешение 1280*800 звук 10 Вт | E12: Яркость 3500 Лм Разрешение 1280*800 звук 10 Вт | F12: Яркость 3500 Лм Разрешение 1280*800 звук 10 Вт | G12: Яркость 3500 Лм Разрешение 1280*800 звук 10 Вт | H12: Яркость 3500 Лм Разрешение 1280*800 звук 10 Вт
B13: Характеристика компьютера | C13: Intel i3/4Gb/SSD120 Windows 10 USB 3.0 - 2шт, Wi-Fi | D13: Intel i3/4Gb/SSD120 Windows 10 USB 3.0 - 2шт, Wi-Fi | E13: Intel i3/4Gb/SSD120 Windows 10 USB 3.0 - 2шт, Wi-Fi | F13: Intel i3/4Gb/SSD120 Windows 10 USB 3.0 - 2шт, Wi-Fi | G13: Intel i3/4Gb/SSD120 Windows 10 USB 3.0 - 2шт, Wi-Fi | H13: Intel i3/4Gb/SSD120 Windows 10 USB 3.0 - 2шт, Wi-Fi
B14: Датчик детекции | C14: Кинект | D14: Кинект | E14: Кинект | F14: Кинект | G14: Кинект | H14: Кинект
B15: Основное программное обеспечение и блок игр на выбор | C15: 1) Программа распознавания касаний. 2) Блок игр: "Интерактивная песочница". 3) Развивающий или развлекательный блок, более 40 игр. | D15: 1) Программа распознавания касаний. 2) Блок игр: "Интерактивная песочница". 3) Развивающий или развлекательный блок, более 40 игр. | E15: 1) Программа распознавания касаний. 2) Блок игр: "Интерактивная песочница". 3) Развивающий или развлекательный блок, более 40 игр. | F15: 1) Программа распознавания касаний. 2) Блок игр: "Интерактивная песочница". 3) Развивающий или развлекательный блок, более 40 игр. | G15: 1) Программа распознавания касаний. 2) Блок игр: "Интерактивная песочница". 3) Развивающий или развлекательный блок, более 40 игр. | H15: 1) Программа распознавания касаний. 2) Блок игр: "Интерактивная песочница". 3) Развивающий или развлекательный блок, более 40 игр.
B16: Дополнительный блок игр | C16: Дополнительный блок: Развлекательный + 30 000 ₽ Развивающий + 30 000 ₽ "Методист" эл. дистрибутив" +15000₽ | D16: Дополнительный блок: Развлекательный + 30 000 ₽ Развивающий + 30 000 ₽ "Методист" эл. дистрибутив +15000₽ | E16: Дополнительный блок: Развлекательный + 30 000 ₽ Развивающий + 30 000 ₽ "Методист" эл. дистрибутив +15000₽ | F16: Дополнительный блок: Развлекательный + 30 000 ₽ Развивающий + 30 000 ₽ "Методист" эл. дистрибутив +15000₽ | G16: Дополнительный блок: Развлекательный + 30 000 ₽ Развивающий + 30 000 ₽ "Методист" эл. дистрибутив+15000₽ | H16: Дополнительный блок: Развлекательный + 30 000 ₽ Развивающий + 30 000 ₽ "Методист" эл. дистрибутив+15000₽
B17: Сенсорный экран для выбора игр | C17: не комплектуется | D17: Сенсорный экран установлен | E17: не комплектуется | F17: Сенсорный экран установлен | G17: Сенсорный экран установлен | H17: Сенсорный экран установлен
B18: Вес | C18: 62 кг | D18: 150 кг | E18: 160 кг | F18: 160 кг | G18: 160 кг | H18: 160 кг
B19: Песок дополнительно | C19: + 12 500 р (70 кг) | D19: + 30 000 р (168 кг) | E19: + 35 000 р (196 кг) | F19: + 35 000 р (196 кг) | G19: + 35 000 р (196 кг) | H19: + 35 000 р (196 кг)
B20: В комплект входят: | C20: 1. Корпус песочницы - 2 детали 2. Проектор 3. Датчик детекции 4. Беспроводные клавиатура и мышь 5. Пульт 6. Методическое пособие 7. Технический паспорт 8. ПО Песочница 9. Сертификат 10. Гарантийный талон 1 год | D20: 1. Корпус (с компьютером, проектором, датчиком детекции) 2. Подставка для корпуса 3. Резервуар для песка 4. Беспроводные клавиатура и мышь 5. Пульт 6. Методическое пособие 7. Технический паспорт 8. ПО Песочница 9. Сертификат 10. Гарантийный талон 1 год | E20: 1. Корпус (с компьютером, проектором,датчиком детекции) 2. Подставка для корпуса 3. Резервуар для песка 4. Беспроводные клавиатура и мышь 5. Пульт 6. Методическое пособие 7. Технический паспорт 8. ПО Песочница 9. Сертификат 10. Гарантийный талон 1 год | F20: 1. Корпус (с компьютером, проектором, датчиком детекции) 2. Подставка для корпуса 3. Резервуар для песка 4. Беспроводные клавиатура и мышь 5. Пульт 6. Методическое пособие 7. Технический паспорт 8. ПО Песочница 9. Сертификат 10. Гарантийный талон 1 год | G20: 1. Корпус (с компьютером, проектором, датчиком детекции) 2. Подставка для корпуса 3. Резервуар для песка 4. Беспроводные клавиатура и мышь 5. Пульт 6. Методическое пособие 7. Технический паспорт 8. ПО Песочница 9. Сертификат 10. Гарантийный талон 1 год | H20: 1. Корпус (с компьютером, проектором, датчиком детекции) 2. Подставка для корпуса 3. Резервуар для песка 4. Беспроводные клавиатура и мышь 5. Пульт 6. Методическое пособие 7. Технический паспорт 8. ПО Песочница 9. Сертификат 10. Гарантийный талон 1 год
B22: Количество мест | C22: 2 | E22: 4 | F22: 4 | G22: 3
B23: Упакованные комплекты
B24: Габариты (м.) / вес (кг.) | C24: а) 1,87*0,15*0,25 | D24: а) 0,8*0,4*0,55 | E24: а) 0,8*0,5*0,55 | F24: а) 0,8*0,5*0,55 | G24: а) 0,8*0,5*0,55 | H24: а) 0,8*0,5*0,55
C25: б) 1*0,6*0,5 | D25: б) 0,95*1,2*0,2 | E25: б) 1,65*1,1*0,25 | F25: б) 1,65*1,1*0,25 | G25: б) 1,65*1,1*0,25 | H25: б) 1,65*1,1*0,25
D26: в)1,6*0,7*0,5 | E26: в) 1,3*1*0,5 | F26: в) 1,3*1*0,5 | G26: в) 1,3*1*0,5 | H26: в) 1,3*1*0,5
D27: г) 1,2*0,9*0,5 | E27: г) 1,7*0,5*0,7 | F27: г) 1,7*0,5*0,7 | G27: г) 1,7*0,5*0,7 | H27: г) 1,7*0,5*0,7
B28: Вес (кг.) | C28: а) 50 | D28: а) 23 | E28: а) 23,5 | F28: а) 23,5 | G28: а) 23,5 | H28: а) 23,5
C29: б) 12 | D29: б) 41 | E29: б) 60 | F29: б) 60 | G29: б) 60 | H29: б) 60
D30: в) 48 | E30: в) 50,5 | F30: в) 50,5 | G30: в) 50,5 | H30: в) 50,5
D31: г) 49 | E31: г) 36,5 | F31: г) 36,5 | G31: г) 36,5 | H31: г) 36,5
B33: В Главное меню | C33: Переход на Прайс-лист

Sheet Кидалки
B2: В Главное меню | C2: Переход на Прайс-лист | D2: ='Прайс лист'!C31 -> Интерактивная стена "Кидалки"
B4: "Кидалки" - трансформируемая игровая среда, которая совершенствует двигательные умения и навыки детей, развивает психофизические качества - силу, быстроту, выносливость, ловкость, повышает самостоятельную двигательную активность, обеспечивает гармоничное физическое развитие.. Взаимодействие детей с интерактивной стеной происходит через касание стены руками либо различными мягкими предметами (мячиками, игрушками и пр.). | F4: Интерактивный комплекс 2 в 1 стена и пол — универсальное оборудование для детских садов, школ, детских развивающих и развлекательных центров. Проекция может быть направлена как на стену, так и на пол. При смене направления проекции не требуется настройка, достаточно просто установить комплект в нужное положение. К комплексу можно приобретать пакеты игр как интерактивного пола, так и стены. И, конечно, на оборудовании будет работать наш Редактор интерактивных заданий. Можно использовать игры в комплекте, создавать свои и проводить любые занятия на полу и стене. • Размер проекции на стене: 3,25 * 1,85 м.; • Размер проекции на полу: 3,13 * 1,73 м.; • Игровой пакет для пола, игровой пакет для стены; • Лазерный проектор с длительным ресурсом работы; • Не требует настройки.
B6: Модель | C6: ='Прайс лист'!C32 -> Интерактивная стена "Кидалки" в корпусе (кинект) | D6: ='Прайс лист'!C33 -> Интерактивная стена "Кидалки" без корпуса | E6: ='Прайс лист'!C34 -> Интерактивная стена "Кидалки" без проектора | F6: ='Прайс лист'!C54 -> Мобильный комплекс 2в1
B8: Базовая цена (включая НДС 7%) | C8: ='Прайс лист'!D32 -> 490000 | D8: ='Прайс лист'!D33 -> 415000 | E8: ='Прайс лист'!D34 -> 310000 | F8: ='Прайс лист'!D55 -> 625000
B9: Характеристики проектора | C9: Яркость 3000 Лм Разрешение 1280*800 звук 10 Вт | D9: Яркость 3500 Лм Разрешение 1280*800 звук 10 Вт | E9: Рекомендуемые характеристики Яркость 3500 Лм Разрешение 1280*800 звук 10 Вт | F9: Яркость 4000 Лм Разрешение 1920*1080 звук 10 Вт
B10: Характеристика компьютера | C10: 3.0 Ghz /8Gb/SSD240 Windows 10 USB 3.0 - 2шт, Wi-Fi | D10: 3.0 Ghz /8Gb/SSD240 Windows 10 USB 3.0 - 2шт, Wi-Fi | E10: 3.0 Ghz /8Gb/SSD240 Windows 10 USB 3.0 - 2шт, Wi-Fi | F10: 3.0 Ghz /4Gb/SSD240 Windows 10
B11: Датчик детекции | C11: Датчик Кинект | D11: Датчики и камера | E11: Датчики и камера | F11: Интерактивный датчик
B12: Основное программное обеспечение включающее блоки игр | C12: 1) Программа распознавания касаний. 2) Блок игр: "Кидалки-Обучалки" | D12: 1) Программа распознавания касаний. 2) Блок игр: "Кидалки-Обучалки" | E12: 1) Программа распознавания касаний. 2) Блок игр: "Кидалки-Обучалки" | F12: 1) Программа распознавания касаний. 2) Блок игр для стены: "Кидалки-Обучалки" 2) Блок игр для пола: "Развивающий" 45 игр или на выбор любой игровой блок для пола
B13: Дополнительный блок игр | C13: Дополнительный блок: "Раскраски" + 10 000 ₽ "Кидалки" + 45 000 ₽ "Спортбол" + 30 000 ₽ "Ожившие рисунки" со скан-модулем +75 000 ₽ "Методист" эл. дистрибутив+15000₽ | D13: Дополнительный блок: "Раскраски" + 10 000 ₽ "Кидалки" + 45 000 ₽ "Спортбол" + 30 000 ₽ "Ожившие рисунки" со скан-модулем +75 000 ₽ "Методист" эл. дистрибутив+15000₽ | E13: Дополнительный блок: "Раскраски" + 10 000 ₽ "Кидалки" + 45 000 ₽ "Спортбол" + 30 000 ₽ "Ожившие рисунки" со скан-модулем +75 000 ₽ "Методист" эл. дистрибутив +15000₽ | F13: Дополнительный блок:Развлекательный не менее 55 игр + 30 000 ₽ Развивающий не менее 55 игр + 30 000 ₽ Оздоровительная физкультура не менее 40 игр+30 000 ₽ "Методист" эл. дистрибутив +15000₽ Раскраски не менее 10 игр+ 10 000 ₽ Спортбол не менее 20игр + 30 000 ₽ Ожившие рисунки не менее 13 эффектов со скан-модулем +75 000 ₽ Кидалки не менее 47 игр + 45 000 ₽
B14: Вес | C14: 25 кг | D14: 10 кг | E14: 6 кг | F14: 45кг
B15: Размер (ВхШхГ) мм. | C15: 450х420х255 | F15: 140х440х730
B16: Возможность управления играми с андроид устройства | C16: Программа для управления + 5 000 ₽ Планшет с программой для управления + 15 000 ₽ | D16: Программа для управления + 5 000 ₽ Планшет с программой для управления + 15 000 ₽ | E16: Программа для управления + 5 000 ₽ Планшет с программой для управления + 15 000 ₽ | F16: Программа для управления + 5 000 ₽ Планшет с программой для управления + 15 000 ₽
B17: Размер изображения на стене | C17: 1.69 х 3м до 2.8 х 5 м | D17: 1.6 х 2.5м до 3.1 х 5 м | E17: Рекомендуемый 1.6 х 2.5м до 3.1 х 5 м | F17: Размер проекции на стене: 3,25 х 1,85 м Размер проекции на полу: 3,13 х 1,73 м
B18: В комплект входят: | C18: 1. Корпус (с компьютером, проектором, датчиком кинект) 2. Крепление 3. Беспроводные клавиатура и мышь 4. Пульт 5. ПО Кидалки 6. Комплект мячей - 12шт 7. Технический паспорт 8. Сертификат 9. Гарантийный талон | D18: 1. Компьютер+крепление 2. Проектор+крепление 3. Настенный датчик - 2шт камера - 1шт. 4. Беспроводные клавиатура и мышь 5. Пульт 6. ПО Кидалки 7. Комплект мячей - 12шт 8. Технический паспорт 9. Сертификат 10. Гарантийный талон | E18: 1. Компьютер+крепление 2. Настенный датчик - 2шт камера - 1шт. 3. Беспроводные клавиатура и мышь 4. ПО Кидалки 5. Комплект мячей - 12шт 6. Технический паспорт 7. Сертификат 8. Гарантийный талон | F18: 1. Единый металический корпус мобильного комплекса 2в1, 2. Подставка для напольной проекции, к которой кроепится комплекс 3. Беспроводные клавиатура и мышь 4. Пульт для проектора 5. Блок игр для стены один или несколько в зависимости от комплектации 6. Блок игр для пола один или несколько в зависимости от комплектации 7. Технический паспорт 8. Сертификат 9. Гарантийный талон 10. Напольное покрытие 11.Комлект мягких мячей-12шт
B20: Количество мест | C20: 1 | D20: 1 | E20: 1 | F20: 1
B21: Габариты (м.) | C21: 0,5*0,5*0,4 | D21: 0,6*0,6*0,6 | E21: 0,4*,0,4*0,25 | F21: 0,95*0,5*0,6
B22: Вес (кг.) | C22: 30 | D22: 15 | E22: 10 | F22: 45
B23: Объём | C23: 0.1 | D23: 0.22 | E23: 0.04 | F23: 0.29
B25: В Главное меню | C25: Переход на Прайс-лист

Sheet Ожившие рисунки
B2: В Главное меню | C2: Переход на Прайс-лист | E2: ='Прайс лист'!C35 -> Интерактивная стена "Ожившие рисунки"
B4: «Ожившие рисунки» — это творческая студия и интерактивный аттракцион в одном. Продукт создан для спокойных творческих занятий. Прекрасно подходит для зоны тихих игр. Дети раскрашивают шаблоны с персонажами игр, а после сканирования рисунки «оживают» — появляются на интерактивной стене, в игре. С ними можно взаимодействовать касаниями: рыбки будут стремительно уплывать, животные издавать звуки, самолеты и ракеты улетать, фигуры – менять траекторию движения. В каждой игре заложен определённый алгоритм действий.
B6: Модель | C6: ='Прайс лист'!C36 -> Интерактивная стена "Ожившие рисунки" в корпусе (кинект) | D6: ='Прайс лист'!C37 -> Интерактивная стена "Ожившие рисунки" без корпуса | E6: ='Прайс лист'!C38 -> Интерактивная стена "Ожившие рисунки" без проектора | F6: ='Прайс лист'!C39 -> Интерактивная стена "Ожившие рисунки" мобильный комплект
B8: Базовая цена (включая НДС 7%) | C8: ='Прайс лист'!D36 -> 520000 | D8: ='Прайс лист'!D37 -> 445000 | E8: ='Прайс лист'!D38 -> 340000 | F8: ='Прайс лист'!D39 -> 520000
B9: Характеристики проектора | C9: Яркость 3000 Лм Разрешение 1280*800 звук 10 Вт | D9: Яркость 3500 Лм Разрешение 1280*800 звук 10 Вт | E9: Рекомендуемые характеристики Яркость 3500 Лм Разрешение 1280*800 звук 10 Вт | F9: Яркость 3000 Лм Разрешение 1280*800 звук 10 Вт
B10: Характеристика компьютера | C10: 3.0 Ghz /8Gb/SSD240 Windows 10 | D10: 3.0 Ghz /8Gb/SSD240 Windows 10 | E10: 3.0 Ghz /8Gb/SSD240 Windows 10 | F10: 3.0 Ghz /8Gb/SSD240 Windows 10
B11: Сканер рисунков | C11: Скан-модуль, цвет черный. Габариты 45,5*34*50см. Камера 3 мегапикселя. | D11: Скан-модуль, цвет черный. Габариты 45,5*34*50см. Камера 3 мегапикселя. | E11: Скан-модуль, цвет черный. Габариты 45,5*34*50см. Камера 3 мегапикселя. | F11: Втроенный в корпус скан-модуль, цвет черный. Габариты 45,5*34*50см. Камера 3 мегапикселя.
B12: Датчик детекции | C12: Датчик Кинект | D12: Датчики и камера | E12: Датчики и камера | F12: Датчики и камера
B13: Основное программное обеспечение включающее блоки игр | C13: 1) Программа распознавания касаний. 2) Блок игр: "Ожившие рисунки" | D13: 1) Программа распознавания касаний. 2) Блок игр: "Ожившие рисунки" | E13: 1) Программа распознавания касаний. 2) Блок игр: "Ожившие рисунки" | F13: 1) Программа распознавания касаний. 2) Блок игр: "Ожившие рисунки"
B14: Дополнительный блок игр | C14: Дополнительный блок: "Раскраски" + 10 000 ₽ "Спортбол" + 30 000 ₽ "Кидалки" + 45 000 ₽ "Методист" эл. дистрибутив+15000₽ | D14: Дополнительный блок: "Раскраски" + 10 000 ₽ "Спортбол" + 30 000 ₽ "Кидалки" + 45 000 ₽ "Интерактивный тир" + 30 000 ₽ "Методист" эл. дистрибутив+15000₽ | E14: Дополнительный блок: "Раскраски" + 10 000 ₽ "Кидалки-обучалки" + 45 000 ₽ "Спортбол" + 30 000 ₽ "Кидалки" + 45 000 ₽ "Интерактивный тир" + 30 000 ₽ "Методист" эл. дистрибутив +15000₽ | F14: Дополнительный блок: "Раскраски" + 10 000 ₽ "Кидалки-обучалки" + 45 000 ₽ "Спортбол" + 30 000 ₽ "Кидалки" + 45 000 ₽ "Интерактивный тир" + 30 000 ₽ "Методист" эл. дистрибутив +15000₽
B15: Размер (ВхШхГ) мм. | C15: 450х420х255 | F15: 1040х485х485
B16: Размер изображения на стене | C16: от 1.69 х 3м до 2.8 х 5 м | D16: от 1.6 х 2.5м до 3.1 х 5 м | E16: от 1.6 х 2.5м до 3.1 х 5 м | F16: от 1.69 х 3м до 2.8 х 5 м
B17: Шаблоны | C17: В свободном доступе, по ссылке | D17: В свободном доступе, по ссылке | E17: В свободном доступе, по ссылке | F17: В свободном доступе, по ссылке
B18: В комплект входят: | C18: 1. Корпус (с компьютером, проектором, датчиком кинект) 2. Крепление 3. Беспроводные клавиатура и мышь 4. Пульт 5. Скан-модуль 6. ПО Ожившие рисунки 7. Технический паспорт 8. Сертификат 9. Гарантийный талон | D18: 1. Компьютер+крепление 2. Проектор+крепление 3. Настенный датчик - 2шт камера - 1шт. 4. Беспроводные клавиатура и мышь 5. Пульт 6. Скан-модуль 7. ПО Ожившие рисунки 8. Технический паспорт 9. Сертификат 10. Гарантийный талон | E18: 1. Компьютер+крепление 2. Настенный датчик - 2шт камера - 1шт. 3. Беспроводные клавиатура и мышь 4. Скан-модуль 5. ПО Ожившие рисунки 6. Технический паспорт 7. Сертификат 8. Гарантийный талон | F18: 1. Мобильная тумба (с компьютером, проектором, камерой, сканером) 2. Пульт к проектору 3. Беспроводные клавиатура и мышь 5. ПО Ожившие рисунки 5. Технический паспорт 6. Сертификат 7. Гарантийный талон
B20: Количество мест: | C20: 1 | D20: 1 | E20: 1 | F20: 1
B21: Упакованные комплекты
B22: Габариты (м.) | C22: а) 0,57*0,54*0,9 | D22: 0,57*0,54*0,9 | E22: 0,57*0,54*0,9 | F22: 1,1*0,5*0,5
C23: б) 0,5*0,5*0,4 | D23: 0,6*0,6*0,8
B24: Вес (кг.) | C24: а) 25 | D24: 50 | E24: 25 | F24: 40
C25: б) 30
B26: Объём | D26: 0.29 | E26: 0.29 | F26: 0.5
B28: В Главное меню | C28: Переход на Прайс-лист

Sheet Спортбол
B2: В Главное меню | C2: Переход на Прайс-лист | D2: ='Прайс лист'!C40 -> Интерактивная стена "Спортбол"
B4: Спортбол превращает любое пространство в интерактивный спортзал. С его помощью можно безопасно знакомить детей с популярными видами спорта, отрабатывать бросковые движения, приобщать детей к активному образу жизни. Популярные спортивные игры в комплекте системы увлекают детей и взрослых. Игры имеют как соревновательный, так и командный режимы. СПОРТБОЛ обеспечивает полезный, интересный досуг и воспитывает коллективный дух! | F4: Интерактивный комплекс 2 в 1 стена и пол — универсальное оборудование для детских садов, школ, детских развивающих и развлекательных центров. Проекция может быть направлена как на стену, так и на пол. При смене направления проекции не требуется настройка, достаточно просто установить комплект в нужное положение. К комплексу можно приобретать пакеты игр как интерактивного пола, так и стены. И, конечно, на оборудовании будет работать наш Редактор интерактивных заданий. Можно использовать игры в комплекте, создавать свои и проводить любые занятия на полу и стене. • Размер проекции на стене: 3,25 * 1,85 м.; • Размер проекции на полу: 3,13 * 1,73 м.; • Игровой пакет для пола, игровой пакет для стены; • Лазерный проектор с длительным ресурсом работы; • Не требует настройки.
B6: Модель | C6: ='Прайс лист'!C41 -> Интерактивная стена "Спортбол" в корпусе (кинект) | D6: ='Прайс лист'!C42 -> Интерактивная стена "Спортбол" без корпуса | E6: ='Прайс лист'!C43 -> Интерактивная стена "Спортбол" без проектора | F6: ='Прайс лист'!C54 -> Мобильный комплекс 2в1
B8: Базовая цена (включая НДС 7%) | C8: ='Прайс лист'!D41 -> 475000 | D8: ='Прайс лист'!D42 -> 400000 | E8: ='Прайс лист'!D43 -> 295000 | F8: ='Прайс лист'!D55 -> 625000
B9: Характеристики проектора | C9: Яркость 3000 Лм Разрешение 1280*800 звук 10 Вт | D9: Яркость 3500 Лм Разрешение 1280*800 звук 10 Вт | E9: Рекомендуемые характеристики Яркость 3500 Лм Разрешение 1280*800 звук 10 Вт | F9: Лазерный проектор - яркость 4000 Лм Разрешение 1920*1080 звук 10 Вт
B10: Характеристика компьютера | C10: 3.0 Ghz /8Gb/SSD240 Windows 10 USB 3.0 - 2шт, Wi-Fi | D10: 3.0 Ghz /8Gb/SSD240 Windows 10 USB 3.0 - 2шт, Wi-Fi | E10: 3.0 Ghz /8Gb/SSD240 Windows 10 USB 3.0 - 2шт, Wi-Fi | F10: 3.0 Ghz /4Gb/SSD240 Windows 10
B11: Датчик детекции | C11: Датчик Кинект | D11: Датчики и камера | E11: Датчики и камера | F11: Интерактивный датчик
B12: Основное программное обеспечение включающее блоки игр | C12: 1) Программа распознавания касаний. 2) Блок игр: "Спортбол" | D12: 1) Программа распознавания касаний. 2) Блок игр: "Спортбол" | E12: 1) Программа распознавания касаний. 2) Блок игр: "Спортбол" | F12: 1) Программа распознавания касаний. 2) Блок игр для стены: "Спортбол" не менее 20 игр 2) Блок игр для пола: "Развивающий" не менее 55 игр или на выбор любой игровой блок для пола
B13: Дополнительный блок игр | C13: Дополнительный блок: "Раскраски" + 10 000 ₽ "Кидалки-обучалки" + 45 000 ₽ "Кидалки" + 45 000 ₽ "Ожившие рисунки" со скан-модулем +75 000 ₽ "Методист" эл. дистрибутив +15000₽ | D13: Дополнительный блок: "Раскраски" + 10 000 ₽ "Кидалки-обучалки" + 45 000 ₽ "Кидалки" + 45 000 ₽ "Ожившие рисунки" со скан-модулем +75 000 ₽ "Методист" эл. дистрибутив +15000₽ | E13: Дополнительный блок: "Раскраски" + 10 000 ₽ "Кидалки-обучалки" + 45 000 ₽ "Кидалки" + 45 000 ₽ "Ожившие рисунки" со скан-модулем +75 000 ₽ "Методист" эл. дистрибутив +15000₽ | F13: Дополнительный блок:Развлекательный не менее 55 игр + 30 000 ₽ Развивающий не менее 55 игр + 30 000 ₽ Оздоровительная физкультура не менее 40 игр+30 000 ₽ "Методист" эл. дистрибутив +15000₽ Раскраски не менее 10 игр+ 10 000 ₽ Спортбол не менее 20игр + 30 000 ₽ Ожившие рисунки не менее 13 эффектов со скан-модулем +75 000 ₽ Кидалки не менее 47 игр + 45 000 ₽
B14: Вес | C14: 25 кг | D14: 10 кг | E14: 6 кг | F14: 40кг
B15: Размер (ВхШхГ) мм. | C15: 450х420х255 | F15: 140х440х730
B16: Возможность управления играми с андроид устройства | C16: Программа для управления + 5 000 ₽ Планшет с программой для управления + 15 000 ₽ | D16: Программа для управления + 5 000 ₽ Планшет с программой для управления + 15 000 ₽ | E16: Программа для управления + 5 000 ₽ Планшет с программой для управления + 15 000 ₽ | F16: Программа для управления + 5 000 ₽ Планшет с программой для управления + 15 000 ₽
B17: Размер изображения на стене | C17: 1.69 х 3м до 2.8 х 5 м | D17: 1.6 х 2.5м до 3.1 х 5 м | E17: Рекомендуемый 1.6 х 2.5м до 3.1 х 5 м | F17: Размер проекции на стене: 3,25 х 1,85 м Размер проекции на полу: 3,13 х 1,73 м
B18: В комплект входят: | C18: 1. Корпус (с компьютером, проектором, датчиком кинект) 2. Крепление 3. Беспроводные клавиатура и мышь 4. Пульт 5. ПО Спортбол 6. Технический паспорт 7. Сертификат 8. Гарантийный талон | D18: 1. Компьютер+крепление 2. Проектор+крепление 3. Настенный датчик - 2шт камера - 1шт. 4. Беспроводные клавиатура и мышь 5. Пульт 6. ПО Спортбол 7. Технический паспорт 8. Сертификат 9. Гарантийный талон | E18: 1. Компьютер+крепление 2. Настенный датчик - 2шт камера - 1шт. 3. Беспроводные клавиатура и мышь 4. ПО Спортбол 5. Технический паспорт 6. Сертификат 7. Гарантийный талон | F18: 1. Единый металический корпус мобильного комплекса 2в1, 2. Подставка для напольной проекции, к которой кроепится комплекс 3. Беспроводные клавиатура и мышь 4. Пульт для проектора 5. Блок игр для стены один или несколько в зависимости от комплектации 6. Блок игр для пола один или несколько в зависимости от комплектации 7. Технический паспорт 8. Сертификат 9. Гарантийный талон 10. Напольное покрытие * Опционально: Комлект мягких мячей-12шт Скан-модуль металлический-единый корпус
B20: Количество мест | C20: 1 | D20: 1 | E20: 1 | F20: 1
B21: Габариты (м.) | C21: 0,5*0,5*0,4 | D21: 0,6*0,6*0,6 | E21: 0,4*,0,4*0,25 | F21: 0,95*0,5*0,6
B22: Вес (кг.) | C22: 30 | D22: 15 | E22: 10 | F22: 45
B23: Объём | C23: 0.1 | D23: 0.22 | E23: 0.04 | F23: 0.29
B25: В Главное меню | C25: Переход на Прайс-лист

Sheet Скалодром
B2: В Главное меню | C2: Переход на Прайс-лист | D2: Интерактивный скалодром
B4: Скалодром «Вершина» совмещает в себе физическую активность при скалолазании и увлекательные интерактивные игры, мотивирующие к движению. Изображение игры проецируется на скальную поверхность, которая крепится к стене и состоит из панелей с зацепами для лазания (приобретается отдельно). Для безопасности скалодром оснащают мягкими матами. Соревновательные игры имеют режим как для одного, так и для двух участников. Вид такой активности безусловно развивает выносливость! • более 20 игр Скалодрома + бесплатное обновление; • большой размер проекции 5*3 метра; • управление играми с планшета (опционально);
B6: Модель | C6: Интерактивный скалодром в корпусе | D6: Интерактивный скалодром без корпуса | E6: Интерактивный скалодром без проектора
B8: Базовая цена (включая НДС 7%) | C8: ='Прайс лист'!D51 -> 475000 | D8: ='Прайс лист'!D52 -> 410000 | E8: ='Прайс лист'!D53 -> 305000
B9: Характеристики проектора | C9: Яркость 3000 Лм Разрешение 1280*800 звук 10 Вт | D9: Яркость 3500 Лм Разрешение 1280*800 звук 10 Вт | E9: Рекомендуемые характеристики Яркость 3500 Лм Разрешение 1280*800 звук 10 Вт
B10: Характеристика компьютера | C10: 3.0 Ghz /8Gb/SSD240 Windows 10 USB 3.0 - 2шт, Wi-Fi | D10: 3.0 Ghz /8Gb/SSD240 Windows 10 USB 3.0 - 2шт, Wi-Fi | E10: 3.0 Ghz /8Gb/SSD240 Windows 10 USB 3.0 - 2шт, Wi-Fi
B11: Датчик детекции | C11: Датчик Кинект | D11: Датчик Кинект | E11: Датчик Кинект
B12: Основное программное обеспечение включающее блоки игр | C12: 1) Программа распознавания касаний. 2) Блок игр: "Скалодром" | D12: 1) Программа распознавания касаний. 2) Блок игр: "Скалодром" | E12: 1) Программа распознавания касаний. 2) Блок игр: "Скалодром"
B13: Вес | C13: 25 кг | D13: 10 кг | E13: 6 кг
B14: Размер (ВхШхГ) мм. | C14: 450х420х255
B15: Возможность управления играми с андроид устройства | C15: Программа для управления + 5 000 ₽ Планшет с программой для управления + 15 000 ₽ | D15: Программа для управления + 5 000 ₽ Планшет с программой для управления + 15 000 ₽ | E15: Программа для управления + 5 000 ₽ Планшет с программой для управления + 15 000 ₽
B16: Размер изображения на стене | C16: 1.69 х 3м до 2.8 х 5 м | D16: 1.6 х 2.5м до 3.1 х 5 м | E16: Рекомендуемый 1.6 х 2.5м до 3.1 х 5 м
B17: В комплект входят: | C17: 1. Корпус (с компьютером, проектором, датчиком кинект) 2. Крепление 3. Беспроводные клавиатура и мышь 4. Пульт 5. ПО Скалодром 6. Технический паспорт 7. Сертификат 8. Гарантийный талон | D17: 1. Компьютер+крепление 2. Проектор+крепление 3. Датчик кинект + крепление 4. Беспроводные клавиатура и мышь 5. Пульт 6. ПО Скалодром 7. Технический паспорт 8. Сертификат 9. Гарантийный талон | E17: 1. Компьютер+крепление 2. Датчик кинект + крепление 3. Беспроводные клавиатура и мышь 4. ПО Скалодром 5. Технический паспорт 6. Сертификат 7. Гарантийный талон
B18: Необходимо приобрести дополнительно: | C18: Необходима скальная стенка или капитальная стена с зацепами и маты. | D18: Необходима скальная стенка или капитальная стена с зацепами и маты. | E18: Необходима скальная стенка или капитальная стена с зацепами и маты.
B20: Количество мест | C20: 1 | D20: 1 | E20: 1
B21: Габариты (м.) | C21: 0,5*0,5*0,4 | D21: 0,6*0,6*0,6 | E21: 0,4*,0,4*0,25
B22: Вес (кг.) | C22: 30 | D22: 15 | E22: 10
B23: Объём | C23: 0.1 | D23: 0.22 | E23: 0.04
B25: В Главное меню | C25: Переход на Прайс-лист
